Workbook

Sheet Rate Explorer
A1: RATE & HOURS EXPLORER — Regime Forfettario
A2: Edit the yellow cells (rate, hours) — everything else recalculates automatically
A4: ASSUMPTIONS — EDIT IF YOU CONFIRM DIFFERENT FIGURES
A5: Parameter | B5: Value | E5: Notes
A6: Teaching coefficient (redditività) | B6: 0.78 | E6: ATECO 85.59.x — confirm exact code with accountant
A7: IT services coefficient (redditività) | B7: 0.67 | E7: ATECO 62.0x "altre attività" group — confirm
A8: INPS Gestione Separata rate | B8: 0.2607 | E8: Assumes no other compulsory pension cover
A9: Tax substitute rate (imposta sostitutiva) | B9: 0.05 | E9: 5% = years 1–5 start-up rate; change to 0.15 to test post-year-5
A11: EMPLOYER BASELINE — REFERENCE ONLY (what the school currently pays)
A12: Item | B12: Monthly (€) | E12: Notes
A13: Gross payable (avg. of your payslips) | B13: 1140.46
A14: INPS employer rate (estimate — unconfirmed) | B14: 0.2381 | E14: You could not confirm this; standard private-sector estimate used
A15: INAIL rate (estimate — unconfirmed) | B15: 0.0025 | E15: Typical low-risk teaching rate; unconfirmed
A16: TFR (severance, from payslip) | B16: 79.92
A17: Lost bonuses (state tax credits, disappear as contractor) | B17: 153.45
A18: ANNUAL employer cost — excl. bonuses | B18: =(B13+B13*B14+B13*B15+B16)*12 -> 17937.296
A19: ANNUAL employer cost — incl. lost bonuses | B19: =(B13+B13*B14+B13*B15+B16+B17)*12 -> 19778.696
A21: YOUR SCENARIOS — EDIT RATE & HOURS FREELY (yellow cells)
A22: Item | B22: Scenario 1 | C22: Scenario 2 | D22: Scenario 3 | E22: Notes
A23: Teaching — Hourly Rate (€) | B23: 18 | C23: 18 | D23: 18
A24: Teaching — Annual Hours | B24: 369 | C24: 389 | D24: 409 | E24: Sc.1: 9h/wk×41wk = 369. Sc.2: +20h. Sc.3: +20h more.
A25: Teaching — Annual Revenue | B25: =B23*B24 -> 6642 | C25: =C23*C24 -> 7002 | D25: =D23*D24 -> 7362
A27: IT Support/Dev — Hourly Rate (€) | B27: 14 | C27: 14 | D27: 14
A28: IT Support/Dev — Annual Hours | B28: 0 | C28: 276 | D28: 552 | E28: Sc.1: none. Sc.2: 6h/wk×46wk=276. Sc.3: 12h/wk×46wk=552.
A29: IT Support/Dev — Annual Revenue | B29: =B27*B28 -> 0 | C29: =C27*C28 -> 3864 | D29: =D27*D28 -> 7728
A31: TOTAL Annual Billable Hours | B31: =B24+B28 -> 369 | C31: =C24+C28 -> 665 | D31: =D24+D28 -> 961
A32: TOTAL Annual Revenue (invoiced) | B32: =B25+B29 -> 6642 | C32: =C25+C29 -> 10866 | D32: =D25+D29 -> 15090
A33: vs Employer Baseline — excl. bonuses (B18) | B33: =B32-$B$18 -> -11295.296 | C33: =C32-$B$18 -> -7071.2961 | D33: =D32-$B$18 -> -2847.2961 | E33: Positive = you invoice more than the school currently pays
A34: vs Employer Baseline — incl. lost bonuses (B19) | B34: =B32-$B$19 -> -13136.696 | C34: =C32-$B$19 -> -8912.6961 | D34: =D32-$B$19 -> -4688.6961 | E34: Positive = you cover the bonus/TFR shortfall too
A36: TAX & CONTRIBUTIONS (Regime Forfettario)
A37: Item | B37: Scenario 1 | C37: Scenario 2 | D37: Scenario 3 | E37: Notes
A38: Taxable Income | B38: =B25*$B$6+B29*$B$7 -> 5180.76 | C38: =C25*$B$6+C29*$B$7 -> 8050.44 | D38: =D25*$B$6+D29*$B$7 -> 10920.12 | E38: Teaching revenue x teaching coeff. + IT revenue x IT coeff.
A39: INPS Gestione Separata | B39: =B38*$B$8 -> 1350.6241 | C39: =C38*$B$8 -> 2098.7497 | D39: =D38*$B$8 -> 2846.8753
A40: Tax Substitute (imposta sostitutiva) | B40: =(B38-B39)*$B$9 -> 191.50679 | C40: =(C38-C39)*$B$9 -> 297.58451 | D40: =(D38-D39)*$B$9 -> 403.66224 | E40: Correctly applied to taxable income AFTER deducting INPS (per Italian law)
A41: Total Tax + Contributions | B41: =B39+B40 -> 1542.1309 | C41: =C39+C40 -> 2396.3342 | D41: =D39+D40 -> 3250.5375
A43: NET ANNUAL (take-home) | B43: =B38-B41 -> 3638.6291 | C43: =C38-C41 -> 5654.1058 | D43: =D38-D41 -> 7669.5825
A44: NET MONTHLY (take-home) | B44: =B43/12 -> 303.21909 | C44: =C43/12 -> 471.17548 | D44: =D43/12 -> 639.13187
A46: EFFECTIVE RESULTS
A47: Item | B47: Scenario 1 | C47: Scenario 2 | D47: Scenario 3 | E47: Notes
A48: Net €/hour — blended (all work) | B48: =B43/B31 -> 9.8607834 | C48: =C43/C31 -> 8.5024147 | D48: =D43/D31 -> 7.980835
...

Sheet Regime Ordinario
A1: REGIME ORDINARIO — Set Your Own Rates
A2: Hourly rates below are independent of Sheet 1. Hours are linked from 'Rate Explorer' (grey cells) — change hours there.
A4: ASSUMPTIONS — EDIT FREELY (independent from Sheet 1)
A5: Parameter | B5: Value | E5: Notes
A6: Deductible expenses (% of revenue) | B6: 0.1 | E6: YOUR real costs - laptop, software, commercialista, travel, etc. Adjust to your real estimate.
A7: INPS Gestione Separata rate | B7: 0.2607 | E7: Same legal rate as Sheet 1 - kept independent here for flexibility
A8: No-tax area threshold (autonomi) | B8: 5500 | E8: 2026: below ~EUR 5,500 taxable income, IRPEF approx EUR 0 (simplified - real mechanism phases in via detrazioni)
A9: IRPEF Bracket 1 ceiling (EUR) | B9: 28000
A10: IRPEF Bracket 1 rate | B10: 0.23
A11: IRPEF Bracket 2 ceiling (EUR) | B11: 50000
A12: IRPEF Bracket 2 rate | B12: 0.33 | E12: 2026 rate: reduced from 35% to 33% by the 2026 Budget Law
A13: IRPEF Bracket 3 rate (above ceiling 2) | B13: 0.43
A14: Regional addizionale (avg.) | B14: 0.0173 | E14: Varies 1.23%-3.33% by region - check your region
A15: Municipal addizionale (avg.) | B15: 0.007 | E15: Varies 0%-0.8% by comune - check yours
A16: VAT rate (IVA) | B16: 0.22 | E16: Added ON TOP of your invoice. Does not affect your net - but the client pays more.
A18: YOUR RATES (edit here) & HOURS (linked from 'Rate Explorer')
A19: Item | B19: Scenario 1 | C19: Scenario 2 | D19: Scenario 3 | E19: Notes
A20: Teaching - Hourly Rate (EUR) | B20: 18 | C20: 18 | D20: 18 | E20: INDEPENDENT of Sheet 1 - set whatever rate you want to test here
A21: Teaching - Annual Hours | B21: ='Rate Explorer'!B24 -> 369 | C21: ='Rate Explorer'!C24 -> 389 | D21: ='Rate Explorer'!D24 -> 409 | E21: Linked from 'Rate Explorer' row 24 - edit hours there, not here
A22: Teaching - Annual Revenue | B22: =B20*B21 -> 6642 | C22: =C20*C21 -> 7002 | D22: =D20*D21 -> 7362
A24: IT Support/Dev - Hourly Rate (EUR) | B24: 14 | C24: 14 | D24: 14 | E24: INDEPENDENT of Sheet 1 - set whatever rate you want to test here
A25: IT Support/Dev - Annual Hours | B25: ='Rate Explorer'!B28 -> 0 | C25: ='Rate Explorer'!C28 -> 276 | D25: ='Rate Explorer'!D28 -> 552 | E25: Linked from 'Rate Explorer' row 28 - edit hours there, not here
A26: IT Support/Dev - Annual Revenue | B26: =B24*B25 -> 0 | C26: =C24*C25 -> 3864 | D26: =D24*D25 -> 7728
A28: TOTAL Annual Hours | B28: =B21+B25 -> 369 | C28: =C21+C25 -> 665 | D28: =D21+D25 -> 961
A29: TOTAL Annual Revenue (compenso) | B29: =B22+B26 -> 6642 | C29: =C22+C26 -> 10866 | D29: =D22+D26 -> 15090
A30: Invoice Total incl. VAT (informational) | B30: =B29*(1+$B$16) -> 8103.24 | C30: =C29*(1+$B$16) -> 13256.52 | D30: =D29*(1+$B$16) -> 18409.8 | E30: What the client actually pays - VAT collected & remitted, doesn't change your net
A32: TAX & CONTRIBUTIONS (Regime Ordinario)
A33: Item | B33: Scenario 1 | C33: Scenario 2 | D33: Scenario 3 | E33: Notes
A34: Deductible Expenses | B34: =B29*$B$6 -> 664.2 | C34: =C29*$B$6 -> 1086.6 | D34: =D29*$B$6 -> 1509
A35: Net Professional Income | B35: =B29-B34 -> 5977.8 | C35: =C29-C34 -> 9779.4 | D35: =D29-D34 -> 13581
A36: INPS Gestione Separata | B36: =B35*$B$7 -> 1558.4125 | C36: =C35*$B$7 -> 2549.4896 | D36: =D35*$B$7 -> 3540.5667
A37: IRPEF Taxable Base (net of INPS) | B37: =B35-B36 -> 4419.3875 | C37: =C35-C36 -> 7229.9104 | D37: =D35-D36 -> 10040.433
A38: IRPEF (progressive, with no-tax area) | B38: =IF(B37<=$B$8,0,MIN(B37,$B$9)*$B$10+MAX(MIN(B37,$B$11)-$B$9,0)*$B$12+MAX(B37-$B$11,0)*$B$13) -> 0 | C38: =IF(C37<=$B$8,0,MIN(C37,$B$9)*$B$10+MAX(MIN(C37,$B$11)-$B$9,0)*$B$12+MAX(C37-$B$11,0)*$B$13) -> 1662.8794 | D38: =IF(D37<=$B$8,0,MIN(D37,$B$9)*$B$10+MAX(MIN(D37,$B$11)-$B$9,0)*$B$12+MAX(D37-$B$11,0)*$B$13) -> 2309.2997 | E38: Simplified: 0 below threshold; otherwise full progressive brackets
A39: Regional + Municipal Addizionali | B39: =IF(B37<=$B$8,0,B37*($B$14+$B$15)) -> 0 | C39: =IF(C37<=$B$8,0,C37*($B$14+$B$15)) -> 175.68682 | D39: =IF(D37<=$B$8,0,D37*($B$14+$B$15)) -> 243.98253
A40: Total Tax (IRPEF + addizionali) | B40: =B38+B39 -> 0 | C40: =C38+C39 -> 1838.5662 | D40: =D38+D39 -> 2553.2822
A42: NET ANNUAL (take-home) | B42: =B35-B36-B40 -> 4419.3875 | C42: =C35-C36-C40 -> 5391.3442 | D42: =D35-D36-D40 -> 7487.1511
A43: NET MONTHLY (take-home) | B43: =B42/12 -> 368.28229 | C43: =C42/12 -> 449.27868 | D43: =D42/12 -> 623.92926
A45: vs EMPLOYER BASELINE - LINKED FROM 'Rate Explorer'
A46: Item | B46: Scenario 1 | C46: Scenario 2 | D46: Scenario 3 | E46: Notes
A47: vs Baseline - excl. bonuses | B47: =B29-'Rate Explorer'!$B$18 -> -11295.296 | C47: =C29-'Rate Explorer'!$B$18 -> -7071.2961 | D47: =D29-'Rate Explorer'!$B$18 -> -2847.2961 | E47: Total revenue invoiced vs what school currently pays (excl. lost bonuses)
...
